Workbook
Name CriticalList: Dropdown_Lists!$C$2:$C$3
Name DirectionList: Dropdown_Lists!$B$2:$B$4
Name GateStatusList: Dropdown_Lists!$E$2:$E$6
Name MetricTypeList: Dropdown_Lists!$A$2:$A$3
Name Period: Dropdown_Lists!$H$2:$H$5
Name ReviewStatusList: Dropdown_Lists!$F$2:$F$4
Name TimelineStatusList: Dropdown_Lists!$G$2:$G$6
Name UnitList: Dropdown_Lists!$D$2:$D$8

Sheet Instructions
A1: Gate Definition & Timeline Pack for PIC
A3: Sumber | B3: Disusun dari file gate_go_no_go_cards (3).html yang diunggah user pada 2026-04-20.
A4: Tujuan workbook | B4: Untuk dibagikan ke PIC agar mereka melengkapi definisi, evidence, status gate, dan update timeline per project.
A5: Bobot gate | B5: Gate 1 = 25%, Gate 2 = 30%, Gate 3 = 25%, Gate 4 = 20%.
A6: Hard gate | B6: Gate 1 dan Gate 3 adalah hard gate. Jika gagal, project tidak layak lanjut meskipun gate lain baik.
A7: Cara pakai | B7: Isi progres aktual hanya di Timeline_Tasks (PIC Start Date dan PIC Actual % Input). Timeline_Periods dan Progress % project akan roll-up otomatis.
A10: Ringkasan Workbook
A11: Total project | B11: =COUNTA(Project_Summary!A2:A200) -> 6
A12: Total gate | B12: =COUNTA(Gate_Definitions!A2:A500) -> 499
A13: Total hard gate | B13: =COUNTIF(Gate_Definitions!D2:D500,"Yes") -> 6
A14: Total timeline task | B14: =COUNTA(Timeline_Tasks!A2:A1000) -> 999
A17: Dropdown reference
A18: Gate status (PIC) | B18: Pass,Conditional,Fail,Not Started
A19: Timeline progress input | B19: Gunakan PIC Actual % Input pada Timeline_Tasks. Tidak lagi memakai status task sebagai penggerak progres.
A20: Reviewer status | B20: Open,In Review,Closed
A22: Panduan Definisi Kolom
A23: Kolom / Istilah | B23: Arti / definisi | C23: Cara isi / contoh | D23: Berlaku di sheet
A24: Hard Gate | B24: Gate kritikal. Jika statusnya Fail, proyek secara prinsip tidak boleh lanjut walaupun gate lain baik. | C24: Di file ini: Gate 1 dan Gate 3 adalah hard gate. | D24: Gate_Definitions
A25: Metric Type | B25: Jenis metric untuk evaluasi. "range" berarti nilai numerik, "select" berarti pilihan status. | C25: range = 92%; select = Pass / Conditional / Fail. | D25: Gate_Metrics
A26: Direction | B26: Arah penilaian metric. "high" berarti makin besar makin baik, "low" berarti makin kecil makin baik. | C26: Precision biasanya high; latency biasanya low. | D26: Gate_Metrics
A27: Current Value | B27: Nilai aktual metric saat ini dari hasil pilot, pengujian, atau implementasi lapangan. | C27: Contoh: uptime 99.1, latency 165, ROI 183. | D27: Gate_Metrics
A28: Pass Threshold | B28: Ambang minimum agar metric dinilai Pass. | C28: Jika direction=high, nilai aktual harus sama atau lebih tinggi dari angka ini. Jika direction=low, nilai aktual harus sama atau lebih rendah dari angka ini. | D28: Gate_Metrics
A29: Conditional Threshold | B29: Ambang tengah untuk status Conditional bila belum mencapai Pass tetapi masih dapat diterima sementara dengan tindak lanjut. | C29: Biasanya dipakai sebagai status warning / perlu improvement. | D29: Gate_Metrics
A30: Min | B30: Batas bawah rentang input untuk metric numerik. | C30: Contoh: 0, 50, atau -100 sesuai karakter metric. | D30: Gate_Metrics
A31: Max | B31: Batas atas rentang input untuk metric numerik. | C31: Contoh: 100 untuk persen, 400 untuk latency, 300 untuk net saving. | D31: Gate_Metrics
A32: Step | B32: Interval kenaikan/perubahan nilai input untuk metric bertipe range. | C32: step 1 = berubah per 1; step 0.1 = berubah per 0,1; step 5 = berubah per 5. | D32: Gate_Metrics
A33: PIC Status | B33: Status penilaian atau update yang diisi PIC. | C33: Gunakan opsi yang sudah disiapkan seperti Pass / Conditional / Fail / Not Started. | D33: Gate_Definitions; Timeline sheets
A34: Reviewer Status | B34: Status review dari evaluator/reviewer setelah PIC mengisi update. | C34: Open / In Review / Closed. | D34: Gate_Definitions; Timeline_Periods
... A38: Evidence Link / Folder | B38: Link folder, dokumen, file bukti, atau referensi evidence pendukung status yang diisi PIC. | C38: Bisa berupa Google Drive folder, dokumen test, minutes, screenshot, atau evidence lain. | D38: Gate_Definitions; Gate_Metrics; Timeline_Tasks
A40: Panduan pengisian kolom kuning
A41: Sheet | B41: Kolom kuning yang diisi PIC | C41: Tujuan | D41: Catatan
A42: Gate_Definitions | B42: PIC Status; PIC Notes / Key Findings; Evidence Link / Folder; PIC Owner; Target Close Date; Reviewer Status | C42: Mengisi hasil evaluasi per gate pada level narasi / governance. | D42: Gunakan untuk menjelaskan status gate secara ringkas namun jelas.
A43: Gate_Metrics | B43: PIC Current Finding; PIC Evidence / Source; PIC Comment; Metric Status | C43: Mengisi kondisi aktual tiap metric dan bukti pendukungnya. | D43: Metric Status sebaiknya konsisten dengan nilai aktual vs threshold.
A44: Timeline_Periods | B44: PIC Update Summary; PIC Risks / Dependencies; PIC Owner; Target Date; Reviewer Status | C44: Mengisi narasi kemajuan per phase/periode. Progress % terhitung otomatis dari Timeline_Tasks. | D44: Jangan input progress manual di sini.
A45: Timeline_Tasks | B45: PIC Actual Owner; PIC Start Date; PIC Actual % Input; PIC Progress Note; Evidence Link; Target Date; Dependency / Blocker | C45: Satu-satunya input progres numerik. Nilai ini yang menggerakkan progress phase/period/project. | D45: Isi 0-100 atau 0%-100%; workbook akan normalisasi otomatis.
A47: Catatan: step hanya relevan untuk metric_type = range. Untuk metric_type = select, cukup gunakan pilihan status seperti Pass / Conditional / Fail.
A49: Update workbook | B49: Ditambahkan kolom Need Support (PIC) pada Project_Summary, dropdown untuk Metric Type / Direction / Critical / Unit pada Gate_Metrics, dan sheet khusus untuk setiap project.
A50: Cara pakai sheet per project | B50: Setiap project sekarang memiliki 1 sheet sendiri untuk dibagikan ke PIC. Sheet gabungan tetap dipertahankan sebagai database all project / consolidated view.
A51: Dropdown Metric Type | B51: Pilihan: range, select. Gunakan range untuk angka/continuous metric, dan select untuk pass/conditional/fail.
A52: Dropdown Direction | B52: Pilihan: high, low. high = makin tinggi makin baik; low = makin rendah makin baik. Boleh dikosongkan jika Metric Type = select.
...

Sheet Project_Summary
A1: Project | B1: Subtitle / Context | C1: Pilot Area | D1: Support Needed | E1: Current Phase | F1: Progress % | G1: Current Period | H1: Next Milestone | I1: Need Support (PIC)
A2: ='Arcas HD'!$B$5 -> Arcas HD | B2: ='Arcas HD'!$B$6 -> Heavy automation use case with high dependency on network, ROC monitoring, and safe fallback control. | C2: ='Arcas HD'!$F$5 -> PAMA BMO2, MTN SMO | D2: ='Arcas HD'!$F$6 -> kebutuhan akomodasi mesh untuk teknisi yang akan menginap di pama dan mtn awal mei, assist terhadap kebutuhan server dan scurity untuk streaming, tahap awal apakah bisa di fasilitasi maintech. | E2: ='Arcas HD'!$B$7 -> Pilot proving & controlled expansion | F2: ='Arcas HD'!$F$7 -> 0.425 | G2: ='Arcas HD'!$B$8 -> Apr–Jun 2026 | H2: ='Arcas HD'!$F$8 -> 0 | I2: ='Arcas HD'!$B$9 -> PAMA dan MTN
A3: ='MGD PC'!$B$5 -> MGD PC | B3: ='MGD PC'!$B$6 -> Precision-guidance pilot where technical accuracy and field consistency are more critical than raw ROI alone. | C3: ='MGD PC'!$F$5 -> PAMA BMO2 | D3: ='MGD PC'!$F$6 -> Positioning quality, operator interface, supervised pilot protocol | E3: ='MGD PC'!$B$7 -> Accuracy stabilization | F3: ='MGD PC'!$F$7 -> 0.53333333 | G3: ='MGD PC'!$B$8 -> Apr–Jun 2026 | H3: ='MGD PC'!$F$8 -> Guidance accuracy closeout for broader field test | I3: ='MGD PC'!$B$9 -> 0
A4: ='Remote Pump'!$B$5 -> Remote Pump | B4: ='Remote Pump'!$B$6 -> Remote operation pilot emphasizing interlock integrity, fail-safe response, and exposure reduction in pump areas. | C4: ='Remote Pump'!$F$5 -> BC SMO - ACI, BC BMO1 - PMO | D4: ='Remote Pump'!$F$6 -> 5G / telemetry network, PLC integration, remote command governance | E4: ='Remote Pump'!$B$7 -> Functional validation & availability proving | F4: ='Remote Pump'!$F$7 | G4: ='Remote Pump'!$B$8 -> Apr–Jun 2026 | H4: ='Remote Pump'!$F$8 -> Interlock sign-off and rollout readiness | I4: ='Remote Pump'!$B$9 -> 0
A5: ='Hauling Fleet Management'!$B$5 -> Hauling Fleet Management | B5: ='Hauling Fleet Management'!$B$6 -> Optimization pilot where dispatch quality, queue reduction, and utilization improvement drive the business case. | C5: ='Hauling Fleet Management'!$F$5 -> MTL BMO1 | D5: ='Hauling Fleet Management'!$F$6 -> Fleet data pipeline, dispatch integration, performance dashboard | E5: ='Hauling Fleet Management'!$B$7 -> Optimization scaling | F5: ='Hauling Fleet Management'!$F$7 | G5: ='Hauling Fleet Management'!$B$8 -> Apr–Jun 2026 | H5: ='Hauling Fleet Management'!$F$8 -> Portfolio-scale dispatch recommendation | I5: ='Hauling Fleet Management'!$B$9 -> 0
A6: ='Mining Eyes Analytics'!$B$5 -> Mining Eyes Analytics | B6: ='Mining Eyes Analytics'!$B$6 -> AI surveillance and analytics pilot where assurance value can be as important as direct cash ROI. | C6: ='Mining Eyes Analytics'!$F$5 -> PAMA BMO2, PAMA GMO, MTN SMO | D6: ='Mining Eyes Analytics'!$F$6 -> 5G infrastructure, cloud, surveillance dashboard (HRZ) | E6: ='Mining Eyes Analytics'!$B$7 -> Coverage improvement & workflow hardening | F6: ='Mining Eyes Analytics'!$F$7 | G6: ='Mining Eyes Analytics'!$B$8 -> Apr–Jun 2026 | H6: ='Mining Eyes Analytics'!$F$8 -> False positive reduction and closure workflow maturity | I6: ='Mining Eyes Analytics'!$B$9 -> 0
A7: ='Remote Dozer'!$B$5 -> Remote Dozer | B7: ='Remote Dozer'!$B$6 -> Remote dozer pilot with strong linkage between technical readiness, safe remote operation, and direct economical value from fuel and efficiency improvement. | C7: ='Remote Dozer'!$F$5 -> Kalimantan OB Disposal | D7: ='Remote Dozer'!$F$6 -> 5G network, remote control station, video telemetry, autonomous zone & dashboard | E7: ='Remote Dozer'!$B$7 -> Integrated readiness and economic proving | F7: ='Remote Dozer'!$F$7 -> 0.75 | G7: ='Remote Dozer'!$B$8 -> Apr–Jun 2026 | H7: ='Remote Dozer'!$F$8 -> Technical + economic pack for scale-up decision | I7: ='Remote Dozer'!$B$9 -> 0

Sheet Gate_Definitions
A1: Project | B1: Gate | C1: Gate Title | D1: Hard Gate | E1: Gate Definition | F1: Project-specific Explanation | G1: What This Gate Confirms | H1: What PIC Needs to Fill | I1: Original Caption | J1: PIC Status | K1: PIC Notes / Key Findings | L1: Evidence Link / Folder | M1: PIC Owner | N1: Target Close Date | O1: Reviewer Status
A2: =IF('Arcas HD'!$A13="","",'Arcas HD'!A13) -> Arcas HD | B2: =IF('Arcas HD'!$A13="","",'Arcas HD'!B13) -> Gate 1 | C2: =IF('Arcas HD'!$A13="","",'Arcas HD'!C13) -> Technical Feasibility | D2: =IF('Arcas HD'!$A13="","",'Arcas HD'!D13) -> Yes | E2: =IF('Arcas HD'!$A13="","",'Arcas HD'!E13) -> Menilai kelayakan teknis dasar solusi sebelum pilot dilanjutkan atau diperluas. | F2: =IF('Arcas HD'!$A13="","",'Arcas HD'!F13) -> Untuk proyek Arcas HD, gate ini fokus pada network readiness, stability, and end-to-end integration. | G2: =IF('Arcas HD'!$A13="","",'Arcas HD'!G13) -> Kesiapan infrastruktur, integrasi sistem, kualitas data/sinyal, stabilitas teknis, uptime, latency, dan reliability. | H2: =IF('Arcas HD'!$A13="","",'Arcas HD'!H13) -> Lengkapi evidence hasil uji teknis, gap teknis terbuka, mitigasi, dan rekomendasi readiness. | I2: =IF('Arcas HD'!$A13="","",'Arcas HD'!I13) -> Network readiness, stability, and end-to-end integration. | J2: =IF('Arcas HD'!$A13="","",'Arcas HD'!#REF!) -> #REF! | K2: =IF('Arcas HD'!$A13="","",'Arcas HD'!K13) -> Kamera front/disposal berfungsi baik (siang/malam). Frekuensi LiDAR tidak stabil (debu & gangguan grounding). Uji coba menggunakan asumsi jarak 6.4m. Menunggu perbaikan power & grounding di WS. | L2: =IF('Arcas HD'!$A13="","",'Arcas HD'!L13) -> https://canva.link/59bd8vwqnm3t9r4 | M2: =IF('Arcas HD'!$A13="","",'Arcas HD'!M13) -> pak ridho | N2: =IF('Arcas HD'!$A13="","",'Arcas HD'!N13) -> juni week 1 | O2: =IF('Arcas HD'!$A13="","",'Arcas HD'!O13) -> in review
A3: =IF('Arcas HD'!$A14="","",'Arcas HD'!A14) -> Arcas HD | B3: =IF('Arcas HD'!$A14="","",'Arcas HD'!B14) -> Gate 2 | C3: =IF('Arcas HD'!$A14="","",'Arcas HD'!C14) -> Performance / Effectiveness | D3: =IF('Arcas HD'!$A14="","",'Arcas HD'!D14) -> Yes | E3: =IF('Arcas HD'!$A14="","",'Arcas HD'!E14) -> Membuktikan bahwa solusi memberi hasil operasional yang relevan dengan tujuan proyek. | F3: =IF('Arcas HD'!$A14="","",'Arcas HD'!F14) -> Untuk proyek Arcas HD, gate ini fokus pada accuracy, intervention quality, and stability across shifts. | G3: =IF('Arcas HD'!$A14="","",'Arcas HD'!G14) -> Akurasi, efektivitas, availability, pengurangan loss, peningkatan produktivitas, atau manfaat performa lain sesuai use case. | H3: =IF('Arcas HD'!$A14="","",'Arcas HD'!H14) -> Lengkapi baseline vs actual, hasil pilot, variasi performa, akar masalah, dan action plan. | I3: =IF('Arcas HD'!$A14="","",'Arcas HD'!I14) -> Accuracy, intervention quality, and stability across shifts. | J3: =IF('Arcas HD'!$A14="","",'Arcas HD'!#REF!) -> #REF! | K3: =IF('Arcas HD'!$A14="","",'Arcas HD'!K14) -> Model YOLO 11 terbukti jauh lebih baik dan responsif dari YOLO 8, meskipun terdapat FPS delay 1 detik dari respon real-time. Alarm berbunyi sesuai limiter target. | L3: =IF('Arcas HD'!$A14="","",'Arcas HD'!L14) -> https://canva.link/59bd8vwqnm3t9r4 | M3: =IF('Arcas HD'!$A14="","",'Arcas HD'!M14) -> pak ridho | N3: =IF('Arcas HD'!$A14="","",'Arcas HD'!N14) -> juni week 1 | O3: =IF('Arcas HD'!$A14="","",'Arcas HD'!O14) -> in review
A4: =IF('Arcas HD'!$A15="","",'Arcas HD'!A15) -> Arcas HD | B4: =IF('Arcas HD'!$A15="","",'Arcas HD'!B15) -> Gate 3 | C4: =IF('Arcas HD'!$A15="","",'Arcas HD'!C15) -> Safety Case & Procedure | D4: =IF('Arcas HD'!$A15="","",'Arcas HD'!D15) -> No | E4: =IF('Arcas HD'!$A15="","",'Arcas HD'!E15) -> Memastikan proyek aman dijalankan dan governance operasionalnya siap. | F4: =IF('Arcas HD'!$A15="","",'Arcas HD'!F15) -> Untuk proyek Arcas HD, gate ini fokus pada emergency stop, override, sop, handover, and drill readiness. | G4: =IF('Arcas HD'!$A15="","",'Arcas HD'!G15) -> SOP, override, fail-safe, escalation path, audit trail, handover, interlock, dan penutupan risiko kritikal. | H4: =IF('Arcas HD'!$A15="","",'Arcas HD'!H15) -> Lengkapi status SOP, hasil simulasi/drill, kontrol keselamatan, approval safety, dan gap residual. | I4: =IF('Arcas HD'!$A15="","",'Arcas HD'!I15) -> Emergency stop, override, SOP, handover, and drill readiness. | J4: =IF('Arcas HD'!$A15="","",'Arcas HD'!#REF!) -> #REF! | K4: =IF('Arcas HD'!$A15="","",'Arcas HD'!K15) -> Sistem peringatan valid direspon oleh operator HD. Tahap selanjutnya akan fokus pada pengujian pengereman otomatis (brake) setelah unit keluar dari WS. | L4: =IF('Arcas HD'!$A15="","",'Arcas HD'!L15) -> https://canva.link/59bd8vwqnm3t9r4 | M4: =IF('Arcas HD'!$A15="","",'Arcas HD'!M15) -> pak ridho | N4: =IF('Arcas HD'!$A15="","",'Arcas HD'!N15) -> juni week 1 | O4: =IF('Arcas HD'!$A15="","",'Arcas HD'!O15) -> open
A5: =IF('Arcas HD'!$A16="","",'Arcas HD'!A16) -> Arcas HD | B5: =IF('Arcas HD'!$A16="","",'Arcas HD'!B16) -> Gate 4 | C5: =IF('Arcas HD'!$A16="","",'Arcas HD'!C16) -> Business / Assurance | D5: =IF('Arcas HD'!$A16="","",'Arcas HD'!D16) -> No | E5: =IF('Arcas HD'!$A16="","",'Arcas HD'!E16) -> Menilai kelayakan scale-up dari sisi bisnis, assurance, atau keekonomian. | F5: =IF('Arcas HD'!$A16="","",'Arcas HD'!F16) -> Untuk proyek Arcas HD, gate ini fokus pada exposure reduction, downtime prevention, and scale rationale. | G5: =IF('Arcas HD'!$A16="","",'Arcas HD'!G16) -> Nilai bisnis, reduction of exposure/loss, assurance value, economic case, payback, ROI, atau justification deployment lebih luas. | H5: =IF('Arcas HD'!$A16="","",'Arcas HD'!H16) -> Lengkapi manfaat terukur, asumsi bisnis/ekonomi, alasan scale-up, risiko bisnis, dan rekomendasi akhir. | I5: =IF('Arcas HD'!$A16="","",'Arcas HD'!I16) -> Exposure reduction, downtime prevention, and scale rationale. | J5: =IF('Arcas HD'!$A16="","",'Arcas HD'!#REF!) -> #REF! | K5: =IF('Arcas HD'!$A16="","",'Arcas HD'!K16) -> Belum dapat dievaluasi. Menunggu full system (termasuk brake) selesai terintegrasi | L5: =IF('Arcas HD'!$A16="","",'Arcas HD'!L16) -> https://canva.link/59bd8vwqnm3t9r4 | M5: =IF('Arcas HD'!$A16="","",'Arcas HD'!M16) -> pak ridho | N5: =IF('Arcas HD'!$A16="","",'Arcas HD'!N16) -> juni week 4 | O5: =IF('Arcas HD'!$A16="","",'Arcas HD'!O16) -> open
A6: =IF('Arcas HD'!$A17="","",'Arcas HD'!A17) -> Arcas HD | B6: =IF('Arcas HD'!$A17="","",'Arcas HD'!B17) -> 0 | C6: =IF('Arcas HD'!$A17="","",'Arcas HD'!C17) -> 0 | D6: =IF('Arcas HD'!$A17="","",'Arcas HD'!D17) -> 0 | E6: =IF('Arcas HD'!$A17="","",'Arcas HD'!E17) -> 0 | F6: =IF('Arcas HD'!$A17="","",'Arcas HD'!F17) -> 0 | G6: =IF('Arcas HD'!$A17="","",'Arcas HD'!G17) -> 0 | H6: =IF('Arcas HD'!$A17="","",'Arcas HD'!H17) -> 0 | ... O6: =IF('Arcas HD'!$A17="","",'Arcas HD'!O17) -> 0
A7: =IF('Arcas HD'!$A18="","",'Arcas HD'!A18) -> Arcas HD | B7: =IF('Arcas HD'!$A18="","",'Arcas HD'!B18) -> 0 | C7: =IF('Arcas HD'!$A18="","",'Arcas HD'!C18) -> 0 | D7: =IF('Arcas HD'!$A18="","",'Arcas HD'!D18) -> 0 | E7: =IF('Arcas HD'!$A18="","",'Arcas HD'!E18) -> 0 | F7: =IF('Arcas HD'!$A18="","",'Arcas HD'!F18) -> 0 | G7: =IF('Arcas HD'!$A18="","",'Arcas HD'!G18) -> 0 | H7: =IF('Arcas HD'!$A18="","",'Arcas HD'!H18) -> 0 | ... O7: =IF('Arcas HD'!$A18="","",'Arcas HD'!O18) -> 0
A8: =IF('Arcas HD'!$A19="","",'Arcas HD'!A19) -> Arcas HD | B8: =IF('Arcas HD'!$A19="","",'Arcas HD'!B19) -> 0 | C8: =IF('Arcas HD'!$A19="","",'Arcas HD'!C19) -> 0 | D8: =IF('Arcas HD'!$A19="","",'Arcas HD'!D19) -> 0 | E8: =IF('Arcas HD'!$A19="","",'Arcas HD'!E19) -> 0 | F8: =IF('Arcas HD'!$A19="","",'Arcas HD'!F19) -> 0 | G8: =IF('Arcas HD'!$A19="","",'Arcas HD'!G19) -> 0 | H8: =IF('Arcas HD'!$A19="","",'Arcas HD'!H19) -> 0 | ... O8: =IF('Arcas HD'!$A19="","",'Arcas HD'!O19) -> 0
A9: =IF('Arcas HD'!$A20="","",'Arcas HD'!A20) -> Arcas HD | B9: =IF('Arcas HD'!$A20="","",'Arcas HD'!B20) -> 0 | C9: =IF('Arcas HD'!$A20="","",'Arcas HD'!C20) -> 0 | D9: =IF('Arcas HD'!$A20="","",'Arcas HD'!D20) -> 0 | E9: =IF('Arcas HD'!$A20="","",'Arcas HD'!E20) -> 0 | F9: =IF('Arcas HD'!$A20="","",'Arcas HD'!F20) -> 0 | G9: =IF('Arcas HD'!$A20="","",'Arcas HD'!G20) -> 0 | H9: =IF('Arcas HD'!$A20="","",'Arcas HD'!H20) -> 0 | ... O9: =IF('Arcas HD'!$A20="","",'Arcas HD'!O20) -> 0
A10: =IF('Arcas HD'!$A21="","",'Arcas HD'!A21) -> Arcas HD | B10: =IF('Arcas HD'!$A21="","",'Arcas HD'!B21) -> 0 | C10: =IF('Arcas HD'!$A21="","",'Arcas HD'!C21) -> 0 | D10: =IF('Arcas HD'!$A21="","",'Arcas HD'!D21) -> 0 | E10: =IF('Arcas HD'!$A21="","",'Arcas HD'!E21) -> 0 | F10: =IF('Arcas HD'!$A21="","",'Arcas HD'!F21) -> 0 | G10: =IF('Arcas HD'!$A21="","",'Arcas HD'!G21) -> 0 | H10: =IF('Arcas HD'!$A21="","",'Arcas HD'!H21) -> 0 | ... O10: =IF('Arcas HD'!$A21="","",'Arcas HD'!O21) -> 0
A11: =IF('Arcas HD'!$A22="","",'Arcas HD'!A22) -> Arcas HD | B11: =IF('Arcas HD'!$A22="","",'Arcas HD'!B22) -> 0 | C11: =IF('Arcas HD'!$A22="","",'Arcas HD'!C22) -> 0 | D11: =IF('Arcas HD'!$A22="","",'Arcas HD'!D22) -> 0 | E11: =IF('Arcas HD'!$A22="","",'Arcas HD'!E22) -> 0 | F11: =IF('Arcas HD'!$A22="","",'Arcas HD'!F22) -> 0 | G11: =IF('Arcas HD'!$A22="","",'Arcas HD'!G22) -> 0 | H11: =IF('Arcas HD'!$A22="","",'Arcas HD'!H22) -> 0 | ... O11: =IF('Arcas HD'!$A22="","",'Arcas HD'!O22) -> 0
A12: =IF('Arcas HD'!$A23="","",'Arcas HD'!A23) -> Arcas HD | B12: =IF('Arcas HD'!$A23="","",'Arcas HD'!B23) -> 0 | C12: =IF('Arcas HD'!$A23="","",'Arcas HD'!C23) -> 0 | D12: =IF('Arcas HD'!$A23="","",'Arcas HD'!D23) -> 0 | E12: =IF('Arcas HD'!$A23="","",'Arcas HD'!E23) -> 0 | F12: =IF('Arcas HD'!$A23="","",'Arcas HD'!F23) -> 0 | G12: =IF('Arcas HD'!$A23="","",'Arcas HD'!G23) -> 0 | H12: =IF('Arcas HD'!$A23="","",'Arcas HD'!H23) -> 0 | ... O12: =IF('Arcas HD'!$A23="","",'Arcas HD'!O23) -> 0
A13: =IF('Arcas HD'!$A24="","",'Arcas HD'!A24) -> Arcas HD | B13: =IF('Arcas HD'!$A24="","",'Arcas HD'!B24) -> 0 | C13: =IF('Arcas HD'!$A24="","",'Arcas HD'!C24) -> 0 | D13: =IF('Arcas HD'!$A24="","",'Arcas HD'!D24) -> 0 | E13: =IF('Arcas HD'!$A24="","",'Arcas HD'!E24) -> 0 | F13: =IF('Arcas HD'!$A24="","",'Arcas HD'!F24) -> 0 | G13: =IF('Arcas HD'!$A24="","",'Arcas HD'!G24) -> 0 | H13: =IF('Arcas HD'!$A24="","",'Arcas HD'!H24) -> 0 | ... O13: =IF('Arcas HD'!$A24="","",'Arcas HD'!O24) -> 0
A14: =IF('Arcas HD'!$A25="","",'Arcas HD'!A25) -> Arcas HD | B14: =IF('Arcas HD'!$A25="","",'Arcas HD'!B25) -> 0 | C14: =IF('Arcas HD'!$A25="","",'Arcas HD'!C25) -> 0 | D14: =IF('Arcas HD'!$A25="","",'Arcas HD'!D25) -> 0 | E14: =IF('Arcas HD'!$A25="","",'Arcas HD'!E25) -> 0 | F14: =IF('Arcas HD'!$A25="","",'Arcas HD'!F25) -> 0 | G14: =IF('Arcas HD'!$A25="","",'Arcas HD'!G25) -> 0 | H14: =IF('Arcas HD'!$A25="","",'Arcas HD'!H25) -> 0 | ... O14: =IF('Arcas HD'!$A25="","",'Arcas HD'!O25) -> 0
A15: =IF('Arcas HD'!$A26="","",'Arcas HD'!A26) -> Arcas HD | B15: =IF('Arcas HD'!$A26="","",'Arcas HD'!B26) -> 0 | C15: =IF('Arcas HD'!$A26="","",'Arcas HD'!C26) -> 0 | D15: =IF('Arcas HD'!$A26="","",'Arcas HD'!D26) -> 0 | E15: =IF('Arcas HD'!$A26="","",'Arcas HD'!E26) -> 0 | F15: =IF('Arcas HD'!$A26="","",'Arcas HD'!F26) -> 0 | G15: =IF('Arcas HD'!$A26="","",'Arcas HD'!G26) -> 0 | H15: =IF('Arcas HD'!$A26="","",'Arcas HD'!H26) -> 0 | ... O15: =IF('Arcas HD'!$A26="","",'Arcas HD'!O26) -> 0
A16: =IF('Arcas HD'!$A27="","",'Arcas HD'!A27) -> Arcas HD | B16: =IF('Arcas HD'!$A27="","",'Arcas HD'!B27) -> 0 | C16: =IF('Arcas HD'!$A27="","",'Arcas HD'!C27) -> 0 | D16: =IF('Arcas HD'!$A27="","",'Arcas HD'!D27) -> 0 | E16: =IF('Arcas HD'!$A27="","",'Arcas HD'!E27) -> 0 | F16: =IF('Arcas HD'!$A27="","",'Arcas HD'!F27) -> 0 | G16: =IF('Arcas HD'!$A27="","",'Arcas HD'!G27) -> 0 | H16: =IF('Arcas HD'!$A27="","",'Arcas HD'!H27) -> 0 | ... O16: =IF('Arcas HD'!$A27="","",'Arcas HD'!O27) -> 0
A17: =IF('Arcas HD'!$A28="","",'Arcas HD'!A28) -> Arcas HD | B17: =IF('Arcas HD'!$A28="","",'Arcas HD'!B28) -> 0 | C17: =IF('Arcas HD'!$A28="","",'Arcas HD'!C28) -> 0 | D17: =IF('Arcas HD'!$A28="","",'Arcas HD'!D28) -> 0 | E17: =IF('Arcas HD'!$A28="","",'Arcas HD'!E28) -> 0 | F17: =IF('Arcas HD'!$A28="","",'Arcas HD'!F28) -> 0 | G17: =IF('Arcas HD'!$A28="","",'Arcas HD'!G28) -> 0 | H17: =IF('Arcas HD'!$A28="","",'Arcas HD'!H28) -> 0 | ... O17: =IF('Arcas HD'!$A28="","",'Arcas HD'!O28) -> 0
... A239: =IF('Arcas HD'!$A250="","",'Arcas HD'!A250) -> Arcas HD | B239: =IF('Arcas HD'!$A250="","",'Arcas HD'!B250) -> 0 | C239: =IF('Arcas HD'!$A250="","",'Arcas HD'!C250) -> 0 | D239: =IF('Arcas HD'!$A250="","",'Arcas HD'!D250) -> 0 | E239: =IF('Arcas HD'!$A250="","",'Arcas HD'!E250) -> 0 | F239: =IF('Arcas HD'!$A250="","",'Arcas HD'!F250) -> 0 | G239: =IF('Arcas HD'!$A250="","",'Arcas HD'!G250) -> 0 | H239: =IF('Arcas HD'!$A250="","",'Arcas HD'!H250) -> 0 | ... O239: =IF('Arcas HD'!$A250="","",'Arcas HD'!O250) -> 0
A240: =IF('MGD PC'!$A13="","",'MGD PC'!A13) -> MGD PC | B240: =IF('MGD PC'!$A13="","",'MGD PC'!B13) -> Gate 1 | C240: =IF('MGD PC'!$A13="","",'MGD PC'!C13) -> Technical Feasibility | D240: =IF('MGD PC'!$A13="","",'MGD PC'!D13) -> Yes | E240: =IF('MGD PC'!$A13="","",'MGD PC'!E13) -> Menilai kelayakan teknis dasar solusi sebelum pilot dilanjutkan atau diperluas. | F240: =IF('MGD PC'!$A13="","",'MGD PC'!F13) -> Untuk proyek MGD PC, gate ini fokus pada sensor reliability, positioning accuracy, and data logging. | G240: =IF('MGD PC'!$A13="","",'MGD PC'!G13) -> Kesiapan infrastruktur, integrasi sistem, kualitas data/sinyal, stabilitas teknis, uptime, latency, dan reliability. | H240: =IF('MGD PC'!$A13="","",'MGD PC'!H13) -> Lengkapi evidence hasil uji teknis, gap teknis terbuka, mitigasi, dan rekomendasi readiness. | I240: =IF('MGD PC'!$A13="","",'MGD PC'!I13) -> Sensor reliability, positioning accuracy, and data logging. | J240: =IF('MGD PC'!$A13="","",'Arcas HD'!J13) -> Conditional | K240: =IF('MGD PC'!$A13="","",'MGD PC'!K13) -> 0 | L240: =IF('MGD PC'!$A13="","",'MGD PC'!L13) -> 0 | M240: =IF('MGD PC'!$A13="","",'MGD PC'!M13) -> 0 | N240: =IF('MGD PC'!$A13="","",'MGD PC'!N13) -> 0 | O240: =IF('MGD PC'!$A13="","",'MGD PC'!O13) -> 0
A241: =IF('MGD PC'!$A14="","",'MGD PC'!A14) -> MGD PC | B241: =IF('MGD PC'!$A14="","",'MGD PC'!B14) -> Gate 2 | C241: =IF('MGD PC'!$A14="","",'MGD PC'!C14) -> Performance / Effectiveness | D241: =IF('MGD PC'!$A14="","",'MGD PC'!D14) -> No | E241: =IF('MGD PC'!$A14="","",'MGD PC'!E14) -> Membuktikan bahwa solusi memberi hasil operasional yang relevan dengan tujuan proyek. | F241: =IF('MGD PC'!$A14="","",'MGD PC'!F14) -> Untuk proyek MGD PC, gate ini fokus pada guidance accuracy, error reduction, and operational acceptance. | G241: =IF('MGD PC'!$A14="","",'MGD PC'!G14) -> Akurasi, efektivitas, availability, pengurangan loss, peningkatan produktivitas, atau manfaat performa lain sesuai use case. | H241: =IF('MGD PC'!$A14="","",'MGD PC'!H14) -> Lengkapi baseline vs actual, hasil pilot, variasi performa, akar masalah, dan action plan. | I241: =IF('MGD PC'!$A14="","",'MGD PC'!I14) -> Guidance accuracy, error reduction, and operational acceptance. | J241: =IF('MGD PC'!$A14="","",'Arcas HD'!J14) -> Conditional | K241: =IF('MGD PC'!$A14="","",'MGD PC'!K14) -> 0 | L241: =IF('MGD PC'!$A14="","",'MGD PC'!L14) -> 0 | M241: =IF('MGD PC'!$A14="","",'MGD PC'!M14) -> 0 | N241: =IF('MGD PC'!$A14="","",'MGD PC'!N14) -> 0 | O241: =IF('MGD PC'!$A14="","",'MGD PC'!O14) -> 0
A242: =IF('MGD PC'!$A15="","",'MGD PC'!A15) -> MGD PC | B242: =IF('MGD PC'!$A15="","",'MGD PC'!B15) -> Gate 3 | C242: =IF('MGD PC'!$A15="","",'MGD PC'!C15) -> Safety Case & Procedure | D242: =IF('MGD PC'!$A15="","",'MGD PC'!D15) -> Yes | E242: =IF('MGD PC'!$A15="","",'MGD PC'!E15) -> Memastikan proyek aman dijalankan dan governance operasionalnya siap. | F242: =IF('MGD PC'!$A15="","",'MGD PC'!F15) -> Untuk proyek MGD PC, gate ini fokus pada manual fallback, override logic, and safe exception handling. | G242: =IF('MGD PC'!$A15="","",'MGD PC'!G15) -> SOP, override, fail-safe, escalation path, audit trail, handover, interlock, dan penutupan risiko kritikal. | H242: =IF('MGD PC'!$A15="","",'MGD PC'!H15) -> Lengkapi status SOP, hasil simulasi/drill, kontrol keselamatan, approval safety, dan gap residual. | I242: =IF('MGD PC'!$A15="","",'MGD PC'!I15) -> Manual fallback, override logic, and safe exception handling. | J242: =IF('MGD PC'!$A15="","",'Arcas HD'!J15) -> Not Started | K242: =IF('MGD PC'!$A15="","",'MGD PC'!K15) -> 0 | L242: =IF('MGD PC'!$A15="","",'MGD PC'!L15) -> 0 | M242: =IF('MGD PC'!$A15="","",'MGD PC'!M15) -> 0 | N242: =IF('MGD PC'!$A15="","",'MGD PC'!N15) -> 0 | O242: =IF('MGD PC'!$A15="","",'MGD PC'!O15) -> 0
A243: =IF('MGD PC'!$A16="","",'MGD PC'!A16) -> MGD PC | B243: =IF('MGD PC'!$A16="","",'MGD PC'!B16) -> Gate 4 | C243: =IF('MGD PC'!$A16="","",'MGD PC'!C16) -> Business / Assurance | D243: =IF('MGD PC'!$A16="","",'MGD PC'!D16) -> No | E243: =IF('MGD PC'!$A16="","",'MGD PC'!E16) -> Menilai kelayakan scale-up dari sisi bisnis, assurance, atau keekonomian. | F243: =IF('MGD PC'!$A16="","",'MGD PC'!F16) -> Untuk proyek MGD PC, gate ini fokus pada operational efficiency, waste reduction, and quality improvement. | G243: =IF('MGD PC'!$A16="","",'MGD PC'!G16) -> Nilai bisnis, reduction of exposure/loss, assurance value, economic case, payback, ROI, atau justification deployment lebih luas. | H243: =IF('MGD PC'!$A16="","",'MGD PC'!H16) -> Lengkapi manfaat terukur, asumsi bisnis/ekonomi, alasan scale-up, risiko bisnis, dan rekomendasi akhir. | I243: =IF('MGD PC'!$A16="","",'MGD PC'!I16) -> Operational efficiency, waste reduction, and quality improvement. | J243: =IF('MGD PC'!$A16="","",'Arcas HD'!J16) -> Conditional | K243: =IF('MGD PC'!$A16="","",'MGD PC'!K16) -> 0 | L243: =IF('MGD PC'!$A16="","",'MGD PC'!L16) -> 0 | M243: =IF('MGD PC'!$A16="","",'MGD PC'!M16) -> 0 | N243: =IF('MGD PC'!$A16="","",'MGD PC'!N16) -> 0 | O243: =IF('MGD PC'!$A16="","",'MGD PC'!O16) -> 0
A244: =IF('MGD PC'!$A17="","",'MGD PC'!A17) -> MGD PC | B244: =IF('MGD PC'!$A17="","",'MGD PC'!B17) -> 0 | C244: =IF('MGD PC'!$A17="","",'MGD PC'!C17) -> 0 | D244: =IF('MGD PC'!$A17="","",'MGD PC'!D17) -> 0 | E244: =IF('MGD PC'!$A17="","",'MGD PC'!E17) -> 0 | F244: =IF('MGD PC'!$A17="","",'MGD PC'!F17) -> 0 | G244: =IF('MGD PC'!$A17="","",'MGD PC'!G17) -> 0 | H244: =IF('MGD PC'!$A17="","",'MGD PC'!H17) -> 0 | ... O244: =IF('MGD PC'!$A17="","",'MGD PC'!O17) -> 0
A245: =IF('MGD PC'!$A18="","",'MGD PC'!A18) -> MGD PC | B245: =IF('MGD PC'!$A18="","",'MGD PC'!B18) -> 0 | C245: =IF('MGD PC'!$A18="","",'MGD PC'!C18) -> 0 | D245: =IF('MGD PC'!$A18="","",'MGD PC'!D18) -> 0 | E245: =IF('MGD PC'!$A18="","",'MGD PC'!E18) -> 0 | F245: =IF('MGD PC'!$A18="","",'MGD PC'!F18) -> 0 | G245: =IF('MGD PC'!$A18="","",'MGD PC'!G18) -> 0 | H245: =IF('MGD PC'!$A18="","",'MGD PC'!H18) -> 0 | ... O245: =IF('MGD PC'!$A18="","",'MGD PC'!O18) -> 0
A246: =IF('MGD PC'!$A19="","",'MGD PC'!A19) -> MGD PC | B246: =IF('MGD PC'!$A19="","",'MGD PC'!B19) -> 0 | C246: =IF('MGD PC'!$A19="","",'MGD PC'!C19) -> 0 | D246: =IF('MGD PC'!$A19="","",'MGD PC'!D19) -> 0 | E246: =IF('MGD PC'!$A19="","",'MGD PC'!E19) -> 0 | F246: =IF('MGD PC'!$A19="","",'MGD PC'!F19) -> 0 | G246: =IF('MGD PC'!$A19="","",'MGD PC'!G19) -> 0 | H246: =IF('MGD PC'!$A19="","",'MGD PC'!H19) -> 0 | ... O246: =IF('MGD PC'!$A19="","",'MGD PC'!O19) -> 0
A247: =IF('MGD PC'!$A20="","",'MGD PC'!A20) -> MGD PC | B247: =IF('MGD PC'!$A20="","",'MGD PC'!B20) -> 0 | C247: =IF('MGD PC'!$A20="","",'MGD PC'!C20) -> 0 | D247: =IF('MGD PC'!$A20="","",'MGD PC'!D20) -> 0 | E247: =IF('MGD PC'!$A20="","",'MGD PC'!E20) -> 0 | F247: =IF('MGD PC'!$A20="","",'MGD PC'!F20) -> 0 | G247: =IF('MGD PC'!$A20="","",'MGD PC'!G20) -> 0 | H247: =IF('MGD PC'!$A20="","",'MGD PC'!H20) -> 0 | ... O247: =IF('MGD PC'!$A20="","",'MGD PC'!O20) -> 0
A248: =IF('MGD PC'!$A21="","",'MGD PC'!A21) -> MGD PC | B248: =IF('MGD PC'!$A21="","",'MGD PC'!B21) -> 0 | C248: =IF('MGD PC'!$A21="","",'MGD PC'!C21) -> 0 | D248: =IF('MGD PC'!$A21="","",'MGD PC'!D21) -> 0 | E248: =IF('MGD PC'!$A21="","",'MGD PC'!E21) -> 0 | F248: =IF('MGD PC'!$A21="","",'MGD PC'!F21) -> 0 | G248: =IF('MGD PC'!$A21="","",'MGD PC'!G21) -> 0 | H248: =IF('MGD PC'!$A21="","",'MGD PC'!H21) -> 0 | ... O248: =IF('MGD PC'!$A21="","",'MGD PC'!O21) -> 0
A249: =IF('MGD PC'!$A22="","",'MGD PC'!A22) -> MGD PC | B249: =IF('MGD PC'!$A22="","",'MGD PC'!B22) -> 0 | C249: =IF('MGD PC'!$A22="","",'MGD PC'!C22) -> 0 | D249: =IF('MGD PC'!$A22="","",'MGD PC'!D22) -> 0 | E249: =IF('MGD PC'!$A22="","",'MGD PC'!E22) -> 0 | F249: =IF('MGD PC'!$A22="","",'MGD PC'!F22) -> 0 | G249: =IF('MGD PC'!$A22="","",'MGD PC'!G22) -> 0 | H249: =IF('MGD PC'!$A22="","",'MGD PC'!H22) -> 0 | ... O249: =IF('MGD PC'!$A22="","",'MGD PC'!O22) -> 0
A250: =IF('MGD PC'!$A23="","",'MGD PC'!A23) -> MGD PC | B250: =IF('MGD PC'!$A23="","",'MGD PC'!B23) -> 0 | C250: =IF('MGD PC'!$A23="","",'MGD PC'!C23) -> 0 | D250: =IF('MGD PC'!$A23="","",'MGD PC'!D23) -> 0 | E250: =IF('MGD PC'!$A23="","",'MGD PC'!E23) -> 0 | F250: =IF('MGD PC'!$A23="","",'MGD PC'!F23) -> 0 | G250: =IF('MGD PC'!$A23="","",'MGD PC'!G23) -> 0 | H250: =IF('MGD PC'!$A23="","",'MGD PC'!H23) -> 0 | ... O250: =IF('MGD PC'!$A23="","",'MGD PC'!O23) -> 0
A251: =IF('MGD PC'!$A24="","",'MGD PC'!A24) -> MGD PC | B251: =IF('MGD PC'!$A24="","",'MGD PC'!B24) -> 0 | C251: =IF('MGD PC'!$A24="","",'MGD PC'!C24) -> 0 | D251: =IF('MGD PC'!$A24="","",'MGD PC'!D24) -> 0 | E251: =IF('MGD PC'!$A24="","",'MGD PC'!E24) -> 0 | F251: =IF('MGD PC'!$A24="","",'MGD PC'!F24) -> 0 | G251: =IF('MGD PC'!$A24="","",'MGD PC'!G24) -> 0 | H251: =IF('MGD PC'!$A24="","",'MGD PC'!H24) -> 0 | ... O251: =IF('MGD PC'!$A24="","",'MGD PC'!O24) -> 0
A252: =IF('MGD PC'!$A25="","",'MGD PC'!A25) -> MGD PC | B252: =IF('MGD PC'!$A25="","",'MGD PC'!B25) -> 0 | C252: =IF('MGD PC'!$A25="","",'MGD PC'!C25) -> 0 | D252: =IF('MGD PC'!$A25="","",'MGD PC'!D25) -> 0 | E252: =IF('MGD PC'!$A25="","",'MGD PC'!E25) -> 0 | F252: =IF('MGD PC'!$A25="","",'MGD PC'!F25) -> 0 | G252: =IF('MGD PC'!$A25="","",'MGD PC'!G25) -> 0 | H252: =IF('MGD PC'!$A25="","",'MGD PC'!H25) -> 0 | ... O252: =IF('MGD PC'!$A25="","",'MGD PC'!O25) -> 0
A253: =IF('MGD PC'!$A26="","",'MGD PC'!A26) -> MGD PC | B253: =IF('MGD PC'!$A26="","",'MGD PC'!B26) -> 0 | C253: =IF('MGD PC'!$A26="","",'MGD PC'!C26) -> 0 | D253: =IF('MGD PC'!$A26="","",'MGD PC'!D26) -> 0 | E253: =IF('MGD PC'!$A26="","",'MGD PC'!E26) -> 0 | F253: =IF('MGD PC'!$A26="","",'MGD PC'!F26) -> 0 | G253: =IF('MGD PC'!$A26="","",'MGD PC'!G26) -> 0 | H253: =IF('MGD PC'!$A26="","",'MGD PC'!H26) -> 0 | ... O253: =IF('MGD PC'!$A26="","",'MGD PC'!O26) -> 0
A254: =IF('MGD PC'!$A27="","",'MGD PC'!A27) -> MGD PC | B254: =IF('MGD PC'!$A27="","",'MGD PC'!B27) -> 0 | C254: =IF('MGD PC'!$A27="","",'MGD PC'!C27) -> 0 | D254: =IF('MGD PC'!$A27="","",'MGD PC'!D27) -> 0 | E254: =IF('MGD PC'!$A27="","",'MGD PC'!E27) -> 0 | F254: =IF('MGD PC'!$A27="","",'MGD PC'!F27) -> 0 | G254: =IF('MGD PC'!$A27="","",'MGD PC'!G27) -> 0 | H254: =IF('MGD PC'!$A27="","",'MGD PC'!H27) -> 0 | ... O254: =IF('MGD PC'!$A27="","",'MGD PC'!O27) -> 0
A255: =IF('MGD PC'!$A28="","",'MGD PC'!A28) -> MGD PC | B255: =IF('MGD PC'!$A28="","",'MGD PC'!B28) -> 0 | C255: =IF('MGD PC'!$A28="","",'MGD PC'!C28) -> 0 | D255: =IF('MGD PC'!$A28="","",'MGD PC'!D28) -> 0 | E255: =IF('MGD PC'!$A28="","",'MGD PC'!E28) -> 0 | F255: =IF('MGD PC'!$A28="","",'MGD PC'!F28) -> 0 | G255: =IF('MGD PC'!$A28="","",'MGD PC'!G28) -> 0 | H255: =IF('MGD PC'!$A28="","",'MGD PC'!H28) -> 0 | ... O255: =IF('MGD PC'!$A28="","",'MGD PC'!O28) -> 0
... A477: =IF('MGD PC'!$A250="","",'MGD PC'!A250) -> MGD PC | B477: =IF('MGD PC'!$A250="","",'MGD PC'!B250) -> 0 | C477: =IF('MGD PC'!$A250="","",'MGD PC'!C250) -> 0 | D477: =IF('MGD PC'!$A250="","",'MGD PC'!D250) -> 0 | E477: =IF('MGD PC'!$A250="","",'MGD PC'!E250) -> 0 | F477: =IF('MGD PC'!$A250="","",'MGD PC'!F250) -> 0 | G477: =IF('MGD PC'!$A250="","",'MGD PC'!G250) -> 0 | H477: =IF('MGD PC'!$A250="","",'MGD PC'!H250) -> 0 | ... O477: =IF('MGD PC'!$A250="","",'MGD PC'!O250) -> 0
A478: =IF('Remote Pump'!$A13="","",'Remote Pump'!A13) -> Remote Pump | B478: =IF('Remote Pump'!$A13="","",'Remote Pump'!B13) -> Gate 1 | C478: =IF('Remote Pump'!$A13="","",'Remote Pump'!C13) -> Technical Feasibility | D478: =IF('Remote Pump'!$A13="","",'Remote Pump'!D13) -> Yes | E478: =IF('Remote Pump'!$A13="","",'Remote Pump'!E13) -> Menilai kelayakan teknis dasar solusi sebelum pilot dilanjutkan atau diperluas. | F478: =IF('Remote Pump'!$A13="","",'Remote Pump'!F13) -> Untuk proyek Remote Pump, gate ini fokus pada command success, telemetry completeness, and communication stability. | G478: =IF('Remote Pump'!$A13="","",'Remote Pump'!G13) -> Kesiapan infrastruktur, integrasi sistem, kualitas data/sinyal, stabilitas teknis, uptime, latency, dan reliability. | H478: =IF('Remote Pump'!$A13="","",'Remote Pump'!H13) -> Lengkapi evidence hasil uji teknis, gap teknis terbuka, mitigasi, dan rekomendasi readiness. | ... O478: =IF('Remote Pump'!$A13="","",'Remote Pump'!O13) -> 0
A479: =IF('Remote Pump'!$A14="","",'Remote Pump'!A14) -> Remote Pump | B479: =IF('Remote Pump'!$A14="","",'Remote Pump'!B14) -> Gate 2 | C479: =IF('Remote Pump'!$A14="","",'Remote Pump'!C14) -> Performance / Effectiveness | D479: =IF('Remote Pump'!$A14="","",'Remote Pump'!D14) -> No | E479: =IF('Remote Pump'!$A14="","",'Remote Pump'!E14) -> Membuktikan bahwa solusi memberi hasil operasional yang relevan dengan tujuan proyek. | F479: =IF('Remote Pump'!$A14="","",'Remote Pump'!F14) -> Untuk proyek Remote Pump, gate ini fokus pada availability, remote-control reliability, and downtime impact. | G479: =IF('Remote Pump'!$A14="","",'Remote Pump'!G14) -> Akurasi, efektivitas, availability, pengurangan loss, peningkatan produktivitas, atau manfaat performa lain sesuai use case. | H479: =IF('Remote Pump'!$A14="","",'Remote Pump'!H14) -> Lengkapi baseline vs actual, hasil pilot, variasi performa, akar masalah, dan action plan. | ... O479: =IF('Remote Pump'!$A14="","",'Remote Pump'!O14) -> 0
A480: =IF('Remote Pump'!$A15="","",'Remote Pump'!A15) -> Remote Pump | B480: =IF('Remote Pump'!$A15="","",'Remote Pump'!B15) -> Gate 3 | C480: =IF('Remote Pump'!$A15="","",'Remote Pump'!C15) -> Safety Case & Procedure | D480: =IF('Remote Pump'!$A15="","",'Remote Pump'!D15) -> Yes | E480: =IF('Remote Pump'!$A15="","",'Remote Pump'!E15) -> Memastikan proyek aman dijalankan dan governance operasionalnya siap. | F480: =IF('Remote Pump'!$A15="","",'Remote Pump'!F15) -> Untuk proyek Remote Pump, gate ini fokus pada interlock, local override, fail-safe loss-of-signal logic. | G480: =IF('Remote Pump'!$A15="","",'Remote Pump'!G15) -> SOP, override, fail-safe, escalation path, audit trail, handover, interlock, dan penutupan risiko kritikal. | H480: =IF('Remote Pump'!$A15="","",'Remote Pump'!H15) -> Lengkapi status SOP, hasil simulasi/drill, kontrol keselamatan, approval safety, dan gap residual. | ... O480: =IF('Remote Pump'!$A15="","",'Remote Pump'!O15) -> 0
A481: =IF('Remote Pump'!$A16="","",'Remote Pump'!A16) -> Remote Pump | B481: =IF('Remote Pump'!$A16="","",'Remote Pump'!B16) -> Gate 4 | C481: =IF('Remote Pump'!$A16="","",'Remote Pump'!C16) -> Business / Assurance | D481: =IF('Remote Pump'!$A16="","",'Remote Pump'!D16) -> No | E481: =IF('Remote Pump'!$A16="","",'Remote Pump'!E16) -> Menilai kelayakan scale-up dari sisi bisnis, assurance, atau keekonomian. | F481: =IF('Remote Pump'!$A16="","",'Remote Pump'!F16) -> Untuk proyek Remote Pump, gate ini fokus pada travel exposure reduction, avoided delays, and operating value. | G481: =IF('Remote Pump'!$A16="","",'Remote Pump'!G16) -> Nilai bisnis, reduction of exposure/loss, assurance value, economic case, payback, ROI, atau justification deployment lebih luas. | H481: =IF('Remote Pump'!$A16="","",'Remote Pump'!H16) -> Lengkapi manfaat terukur, asumsi bisnis/ekonomi, alasan scale-up, risiko bisnis, dan rekomendasi akhir. | ... O481: =IF('Remote Pump'!$A16="","",'Remote Pump'!O16) -> 0
A482: =IF('Remote Pump'!$A17="","",'Remote Pump'!A17) -> Remote Pump | B482: =IF('Remote Pump'!$A17="","",'Remote Pump'!B17) -> 0 | C482: =IF('Remote Pump'!$A17="","",'Remote Pump'!C17) -> 0 | D482: =IF('Remote Pump'!$A17="","",'Remote Pump'!D17) -> 0 | E482: =IF('Remote Pump'!$A17="","",'Remote Pump'!E17) -> 0 | F482: =IF('Remote Pump'!$A17="","",'Remote Pump'!F17) -> 0 | G482: =IF('Remote Pump'!$A17="","",'Remote Pump'!G17) -> 0 | H482: =IF('Remote Pump'!$A17="","",'Remote Pump'!H17) -> 0 | ... O482: =IF('Remote Pump'!$A17="","",'Remote Pump'!O17) -> 0
...

Sheet Gate_Metrics
A1: Project | B1: Gate | C1: Gate Title | D1: Metric Name | E1: Metric Description | F1: Metric Type | G1: Direction | H1: Critical | I1: Unit | J1: Current Value | K1: Pass Threshold | L1: Conditional Threshold | M1: Min | N1: Max | O1: Step | P1: PIC Current Finding | Q1: PIC Evidence / Source | R1: PIC Comment | S1: Metric Status
A2: =IF('Arcas HD'!$Q13="","",'Arcas HD'!Q13) -> Arcas HD | B2: =IF('Arcas HD'!$Q13="","",'Arcas HD'!R13) -> Gate 1 | C2: =IF('Arcas HD'!$Q13="","",'Arcas HD'!S13) -> Technical Feasibility | D2: =IF('Arcas HD'!$Q13="","",'Arcas HD'!T13) -> Instalasi power & converter 12V - Setup jaringan (router/modem) - Uji koneksi remote Uji koneksi tanpa streaming Uji remote basic control | E2: =IF('Arcas HD'!$Q13="","",'Arcas HD'!U13) -> Network uptime stabil Packet loss rendah Respons koneksi | F2: =IF('Arcas HD'!$Q13="","",'Arcas HD'!V13) -> system | G2: =IF('Arcas HD'!$Q13="","",'Arcas HD'!W13) -> high | H2: =IF('Arcas HD'!$Q13="","",'Arcas HD'!X13) -> No | ... S2: =IF('Arcas HD'!$Q13="","",'Arcas HD'!AI13) -> pass
A3: =IF('Arcas HD'!$Q14="","",'Arcas HD'!Q14) -> Arcas HD | B3: =IF('Arcas HD'!$Q14="","",'Arcas HD'!R14) -> Gate 1 | C3: =IF('Arcas HD'!$Q14="","",'Arcas HD'!S14) -> Technical Feasibility | D3: =IF('Arcas HD'!$Q14="","",'Arcas HD'!T14) -> Testing YOLO lokal (tanpa streaming) - Testing RTSP streaming Uji VLC / RTSP push | E3: =IF('Arcas HD'!$Q14="","",'Arcas HD'!U14) -> Round-trip response delay during operation dan Mampu mendeteksi tanggulan dan air dalam conf 0.8 rata rata | F3: =IF('Arcas HD'!$Q14="","",'Arcas HD'!V14) -> deteksi | G3: =IF('Arcas HD'!$Q14="","",'Arcas HD'!W14) -> low | H3: =IF('Arcas HD'!$Q14="","",'Arcas HD'!X14) -> Yes | ... S3: =IF('Arcas HD'!$Q14="","",'Arcas HD'!AI14) -> Conditional
A4: =IF('Arcas HD'!$Q16="","",'Arcas HD'!Q16) -> Arcas HD | B4: =IF('Arcas HD'!$Q16="","",'Arcas HD'!R16) -> Gate 1 | C4: =IF('Arcas HD'!$Q16="","",'Arcas HD'!S16) -> Technical Feasibility | D4: =IF('Arcas HD'!$Q16="","",'Arcas HD'!T16) -> Setup logging system - Monitoring koneksi end-to-end, Logging error & event | E4: =IF('Arcas HD'!$Q16="","",'Arcas HD'!U16) -> Status monitoring aktif 100% node terbaca Data tersimpan = Tidak ada loss log >5% | F4: =IF('Arcas HD'!$Q16="","",'Arcas HD'!V16) -> select | G4: =IF('Arcas HD'!$Q16="","",'Arcas HD'!W16) -> high | H4: =IF('Arcas HD'!$Q16="","",'Arcas HD'!X16) -> Yes | ... S4: =IF('Arcas HD'!$Q16="","",'Arcas HD'!AI16) -> Need Check
A5: =IF('Arcas HD'!$Q17="","",'Arcas HD'!Q17) -> Arcas HD | B5: =IF('Arcas HD'!$Q17="","",'Arcas HD'!R17) -> Gate 2 | C5: =IF('Arcas HD'!$Q17="","",'Arcas HD'!S17) -> Performance / Effectiveness | D5: =IF('Arcas HD'!$Q17="","",'Arcas HD'!T17) -> Precision | E5: =IF('Arcas HD'!$Q17="","",'Arcas HD'!U17) -> Akurasi deteksi ≥ 90% Noise detection < 10% | F5: =IF('Arcas HD'!$Q17="","",'Arcas HD'!V17) -> range | G5: =IF('Arcas HD'!$Q17="","",'Arcas HD'!W17) -> high | H5: =IF('Arcas HD'!$Q17="","",'Arcas HD'!X17) -> No | ... S5: =IF('Arcas HD'!$Q17="","",'Arcas HD'!AI17) -> Pass
A6: =IF('Arcas HD'!$Q18="","",'Arcas HD'!Q18) -> Arcas HD | B6: =IF('Arcas HD'!$Q18="","",'Arcas HD'!R18) -> Gate 2 | C6: =IF('Arcas HD'!$Q18="","",'Arcas HD'!S18) -> Performance / Effectiveness | D6: =IF('Arcas HD'!$Q18="","",'Arcas HD'!T18) -> Recall | E6: =IF('Arcas HD'!$Q18="","",'Arcas HD'!U18) -> Stabilitas sensor = Tidak ada spike noise Coverage deteksi ≥ 85% Range efektif ≥ 6 meter stabil | F6: =IF('Arcas HD'!$Q18="","",'Arcas HD'!V18) -> system | G6: =IF('Arcas HD'!$Q18="","",'Arcas HD'!W18) -> high | H6: =IF('Arcas HD'!$Q18="","",'Arcas HD'!X18) -> No | ... S6: =IF('Arcas HD'!$Q18="","",'Arcas HD'!AI18) -> Conditional
A7: =IF('Arcas HD'!$Q19="","",'Arcas HD'!Q19) -> Arcas HD | B7: =IF('Arcas HD'!$Q19="","",'Arcas HD'!R19) -> Gate 3 | C7: =IF('Arcas HD'!$Q19="","",'Arcas HD'!S19) -> Safety Case & Procedure | D7: =IF('Arcas HD'!$Q19="","",'Arcas HD'!T19) -> SOP readiness | E7: =IF('Arcas HD'!$Q19="","",'Arcas HD'!U19) -> Procedure and handover governance completion. | F7: =IF('Arcas HD'!$Q19="","",'Arcas HD'!V19) -> select | G7: =IF('Arcas HD'!$Q19="","",'Arcas HD'!W19) -> 0 | H7: =IF('Arcas HD'!$Q19="","",'Arcas HD'!X19) -> Yes | ... S7: =IF('Arcas HD'!$Q19="","",'Arcas HD'!AI19) -> Not Started
A8: =IF('Arcas HD'!$Q20="","",'Arcas HD'!Q20) -> Arcas HD | B8: =IF('Arcas HD'!$Q20="","",'Arcas HD'!R20) -> Gate 3 | C8: =IF('Arcas HD'!$Q20="","",'Arcas HD'!S20) -> Safety Case & Procedure | D8: =IF('Arcas HD'!$Q20="","",'Arcas HD'!T20) -> Field drill | E8: =IF('Arcas HD'!$Q20="","",'Arcas HD'!U20) -> Simulation and field drill outcome. | F8: =IF('Arcas HD'!$Q20="","",'Arcas HD'!V20) -> select | G8: =IF('Arcas HD'!$Q20="","",'Arcas HD'!W20) -> 0 | H8: =IF('Arcas HD'!$Q20="","",'Arcas HD'!X20) -> Yes | ... S8: =IF('Arcas HD'!$Q20="","",'Arcas HD'!AI20) -> Not Started
A9: =IF('Arcas HD'!$Q21="","",'Arcas HD'!Q21) -> Arcas HD | B9: =IF('Arcas HD'!$Q21="","",'Arcas HD'!R21) -> Gate 4 | C9: =IF('Arcas HD'!$Q21="","",'Arcas HD'!S21) -> Business / Assurance | D9: =IF('Arcas HD'!$Q21="","",'Arcas HD'!T21) -> Exposure reduction | E9: =IF('Arcas HD'!$Q21="","",'Arcas HD'!U21) -> Index of direct exposure removal from hazard zone. | F9: =IF('Arcas HD'!$Q21="","",'Arcas HD'!V21) -> range | G9: =IF('Arcas HD'!$Q21="","",'Arcas HD'!W21) -> high | H9: =IF('Arcas HD'!$Q21="","",'Arcas HD'!X21) -> No | ... S9: =IF('Arcas HD'!$Q21="","",'Arcas HD'!AI21) -> Not Started
A10: =IF('Arcas HD'!$Q22="","",'Arcas HD'!Q22) -> Arcas HD | B10: =IF('Arcas HD'!$Q22="","",'Arcas HD'!R22) -> Gate 4 | C10: =IF('Arcas HD'!$Q22="","",'Arcas HD'!S22) -> Business / Assurance | D10: =IF('Arcas HD'!$Q22="","",'Arcas HD'!T22) -> Business case quality | E10: =IF('Arcas HD'!$Q22="","",'Arcas HD'!U22) -> Overall economic and assurance justification. | F10: =IF('Arcas HD'!$Q22="","",'Arcas HD'!V22) -> select | G10: =IF('Arcas HD'!$Q22="","",'Arcas HD'!W22) -> 0 | H10: =IF('Arcas HD'!$Q22="","",'Arcas HD'!X22) -> No | ... S10: =IF('Arcas HD'!$Q22="","",'Arcas HD'!AI22) -> Not Started
A11: =IF('Arcas HD'!$Q23="","",'Arcas HD'!Q23) -> Arcas HD | B11: =IF('Arcas HD'!$Q23="","",'Arcas HD'!R23) -> 0 | C11: =IF('Arcas HD'!$Q23="","",'Arcas HD'!S23) -> 0 | D11: =IF('Arcas HD'!$Q23="","",'Arcas HD'!T23) -> 0 | E11: =IF('Arcas HD'!$Q23="","",'Arcas HD'!U23) -> 0 | F11: =IF('Arcas HD'!$Q23="","",'Arcas HD'!V23) -> 0 | G11: =IF('Arcas HD'!$Q23="","",'Arcas HD'!W23) -> 0 | H11: =IF('Arcas HD'!$Q23="","",'Arcas HD'!X23) -> 0 | ... S11: =IF('Arcas HD'!$Q23="","",'Arcas HD'!AI23) -> 0
A12: =IF('Arcas HD'!$Q24="","",'Arcas HD'!Q24) -> Arcas HD | B12: =IF('Arcas HD'!$Q24="","",'Arcas HD'!R24) -> 0 | C12: =IF('Arcas HD'!$Q24="","",'Arcas HD'!S24) -> 0 | D12: =IF('Arcas HD'!$Q24="","",'Arcas HD'!T24) -> 0 | E12: =IF('Arcas HD'!$Q24="","",'Arcas HD'!U24) -> 0 | F12: =IF('Arcas HD'!$Q24="","",'Arcas HD'!V24) -> 0 | G12: =IF('Arcas HD'!$Q24="","",'Arcas HD'!W24) -> 0 | H12: =IF('Arcas HD'!$Q24="","",'Arcas HD'!X24) -> 0 | ... S12: =IF('Arcas HD'!$Q24="","",'Arcas HD'!AI24) -> 0
A13: =IF('Arcas HD'!$Q25="","",'Arcas HD'!Q25) -> Arcas HD | B13: =IF('Arcas HD'!$Q25="","",'Arcas HD'!R25) -> 0 | C13: =IF('Arcas HD'!$Q25="","",'Arcas HD'!S25) -> 0 | D13: =IF('Arcas HD'!$Q25="","",'Arcas HD'!T25) -> 0 | E13: =IF('Arcas HD'!$Q25="","",'Arcas HD'!U25) -> 0 | F13: =IF('Arcas HD'!$Q25="","",'Arcas HD'!V25) -> 0 | G13: =IF('Arcas HD'!$Q25="","",'Arcas HD'!W25) -> 0 | H13: =IF('Arcas HD'!$Q25="","",'Arcas HD'!X25) -> 0 | ... S13: =IF('Arcas HD'!$Q25="","",'Arcas HD'!AI25) -> 0
A14: =IF('Arcas HD'!$Q26="","",'Arcas HD'!Q26) -> Arcas HD | B14: =IF('Arcas HD'!$Q26="","",'Arcas HD'!R26) -> 0 | C14: =IF('Arcas HD'!$Q26="","",'Arcas HD'!S26) -> 0 | D14: =IF('Arcas HD'!$Q26="","",'Arcas HD'!T26) -> 0 | E14: =IF('Arcas HD'!$Q26="","",'Arcas HD'!U26) -> 0 | F14: =IF('Arcas HD'!$Q26="","",'Arcas HD'!V26) -> 0 | G14: =IF('Arcas HD'!$Q26="","",'Arcas HD'!W26) -> 0 | H14: =IF('Arcas HD'!$Q26="","",'Arcas HD'!X26) -> 0 | ... S14: =IF('Arcas HD'!$Q26="","",'Arcas HD'!AI26) -> 0
A15: =IF('Arcas HD'!$Q27="","",'Arcas HD'!Q27) -> Arcas HD | B15: =IF('Arcas HD'!$Q27="","",'Arcas HD'!R27) -> 0 | C15: =IF('Arcas HD'!$Q27="","",'Arcas HD'!S27) -> 0 | D15: =IF('Arcas HD'!$Q27="","",'Arcas HD'!T27) -> 0 | E15: =IF('Arcas HD'!$Q27="","",'Arcas HD'!U27) -> 0 | F15: =IF('Arcas HD'!$Q27="","",'Arcas HD'!V27) -> 0 | G15: =IF('Arcas HD'!$Q27="","",'Arcas HD'!W27) -> 0 | H15: =IF('Arcas HD'!$Q27="","",'Arcas HD'!X27) -> 0 | ... S15: =IF('Arcas HD'!$Q27="","",'Arcas HD'!AI27) -> 0
... A239: =IF('Arcas HD'!$Q251="","",'Arcas HD'!Q251) -> Arcas HD | B239: =IF('Arcas HD'!$Q251="","",'Arcas HD'!R251) -> 0 | C239: =IF('Arcas HD'!$Q251="","",'Arcas HD'!S251) -> 0 | D239: =IF('Arcas HD'!$Q251="","",'Arcas HD'!T251) -> 0 | E239: =IF('Arcas HD'!$Q251="","",'Arcas HD'!U251) -> 0 | F239: =IF('Arcas HD'!$Q251="","",'Arcas HD'!V251) -> 0 | G239: =IF('Arcas HD'!$Q251="","",'Arcas HD'!W251) -> 0 | H239: =IF('Arcas HD'!$Q251="","",'Arcas HD'!X251) -> 0 | ... S239: =IF('Arcas HD'!$Q251="","",'Arcas HD'!AI251) -> 0
A240: =IF('MGD PC'!$Q13="","",'MGD PC'!Q13) -> MGD PC | B240: =IF('MGD PC'!$Q13="","",'MGD PC'!R13) -> Gate 1 | C240: =IF('MGD PC'!$Q13="","",'MGD PC'!S13) -> Technical Feasibility | D240: =IF('MGD PC'!$Q13="","",'MGD PC'!T13) -> Position stability | E240: =IF('MGD PC'!$Q13="","",'MGD PC'!U13) -> Stability of location/guidance reference. | F240: =IF('MGD PC'!$Q13="","",'MGD PC'!V13) -> range | G240: =IF('MGD PC'!$Q13="","",'MGD PC'!W13) -> high | H240: =IF('MGD PC'!$Q13="","",'MGD PC'!X13) -> No | ... S240: =IF('MGD PC'!$Q13="","",'MGD PC'!AI13) -> 0
A241: =IF('MGD PC'!$Q14="","",'MGD PC'!Q14) -> MGD PC | B241: =IF('MGD PC'!$Q14="","",'MGD PC'!R14) -> Gate 1 | C241: =IF('MGD PC'!$Q14="","",'MGD PC'!S14) -> Technical Feasibility | D241: =IF('MGD PC'!$Q14="","",'MGD PC'!T14) -> Data completeness | E241: =IF('MGD PC'!$Q14="","",'MGD PC'!U14) -> Availability of pilot evidence for analysis. | F241: =IF('MGD PC'!$Q14="","",'MGD PC'!V14) -> range | G241: =IF('MGD PC'!$Q14="","",'MGD PC'!W14) -> high | H241: =IF('MGD PC'!$Q14="","",'MGD PC'!X14) -> No | ... S241: =IF('MGD PC'!$Q14="","",'MGD PC'!AI14) -> 0
A242: =IF('MGD PC'!$Q15="","",'MGD PC'!Q15) -> MGD PC | B242: =IF('MGD PC'!$Q15="","",'MGD PC'!R15) -> Gate 1 | C242: =IF('MGD PC'!$Q15="","",'MGD PC'!S15) -> Technical Feasibility | D242: =IF('MGD PC'!$Q15="","",'MGD PC'!T15) -> System uptime | E242: =IF('MGD PC'!$Q15="","",'MGD PC'!U15) -> Application and field support uptime. | F242: =IF('MGD PC'!$Q15="","",'MGD PC'!V15) -> range | G242: =IF('MGD PC'!$Q15="","",'MGD PC'!W15) -> high | H242: =IF('MGD PC'!$Q15="","",'MGD PC'!X15) -> Yes | ... S242: =IF('MGD PC'!$Q15="","",'MGD PC'!AI15) -> 0
A243: =IF('MGD PC'!$Q16="","",'MGD PC'!Q16) -> MGD PC | B243: =IF('MGD PC'!$Q16="","",'MGD PC'!R16) -> Gate 2 | C243: =IF('MGD PC'!$Q16="","",'MGD PC'!S16) -> Performance / Effectiveness | D243: =IF('MGD PC'!$Q16="","",'MGD PC'!T16) -> Guidance accuracy | E243: =IF('MGD PC'!$Q16="","",'MGD PC'!U16) -> Accuracy of field guidance versus target. | F243: =IF('MGD PC'!$Q16="","",'MGD PC'!V16) -> range | G243: =IF('MGD PC'!$Q16="","",'MGD PC'!W16) -> high | H243: =IF('MGD PC'!$Q16="","",'MGD PC'!X16) -> No | ... S243: =IF('MGD PC'!$Q16="","",'MGD PC'!AI16) -> 0
A244: =IF('MGD PC'!$Q17="","",'MGD PC'!Q17) -> MGD PC | B244: =IF('MGD PC'!$Q17="","",'MGD PC'!R17) -> Gate 2 | C244: =IF('MGD PC'!$Q17="","",'MGD PC'!S17) -> Performance / Effectiveness | D244: =IF('MGD PC'!$Q17="","",'MGD PC'!T17) -> Rework reduction | E244: =IF('MGD PC'!$Q17="","",'MGD PC'!U17) -> Reduction in repeated work or adjustment. | F244: =IF('MGD PC'!$Q17="","",'MGD PC'!V17) -> range | G244: =IF('MGD PC'!$Q17="","",'MGD PC'!W17) -> high | H244: =IF('MGD PC'!$Q17="","",'MGD PC'!X17) -> No | ... S244: =IF('MGD PC'!$Q17="","",'MGD PC'!AI17) -> 0
A245: =IF('MGD PC'!$Q18="","",'MGD PC'!Q18) -> MGD PC | B245: =IF('MGD PC'!$Q18="","",'MGD PC'!R18) -> Gate 2 | C245: =IF('MGD PC'!$Q18="","",'MGD PC'!S18) -> Performance / Effectiveness | D245: =IF('MGD PC'!$Q18="","",'MGD PC'!T18) -> User acceptance | E245: =IF('MGD PC'!$Q18="","",'MGD PC'!U18) -> Supervisor/operator willingness to use the solution. | F245: =IF('MGD PC'!$Q18="","",'MGD PC'!V18) -> range | G245: =IF('MGD PC'!$Q18="","",'MGD PC'!W18) -> high | H245: =IF('MGD PC'!$Q18="","",'MGD PC'!X18) -> No | ... S245: =IF('MGD PC'!$Q18="","",'MGD PC'!AI18) -> 0
A246: =IF('MGD PC'!$Q19="","",'MGD PC'!Q19) -> MGD PC | B246: =IF('MGD PC'!$Q19="","",'MGD PC'!R19) -> Gate 3 | C246: =IF('MGD PC'!$Q19="","",'MGD PC'!S19) -> Safety Case & Procedure | D246: =IF('MGD PC'!$Q19="","",'MGD PC'!T19) -> Override readiness | E246: =IF('MGD PC'!$Q19="","",'MGD PC'!U19) -> Manual fallback and override usability. | F246: =IF('MGD PC'!$Q19="","",'MGD PC'!V19) -> select | G246: =IF('MGD PC'!$Q19="","",'MGD PC'!W19) -> 0 | H246: =IF('MGD PC'!$Q19="","",'MGD PC'!X19) -> Yes | ... S246: =IF('MGD PC'!$Q19="","",'MGD PC'!AI19) -> 0
A247: =IF('MGD PC'!$Q20="","",'MGD PC'!Q20) -> MGD PC | B247: =IF('MGD PC'!$Q20="","",'MGD PC'!R20) -> Gate 3 | C247: =IF('MGD PC'!$Q20="","",'MGD PC'!S20) -> Safety Case & Procedure | D247: =IF('MGD PC'!$Q20="","",'MGD PC'!T20) -> Pilot SOP | E247: =IF('MGD PC'!$Q20="","",'MGD PC'!U20) -> Approved procedure for assisted/manual operation. | F247: =IF('MGD PC'!$Q20="","",'MGD PC'!V20) -> select | G247: =IF('MGD PC'!$Q20="","",'MGD PC'!W20) -> 0 | H247: =IF('MGD PC'!$Q20="","",'MGD PC'!X20) -> Yes | ... S247: =IF('MGD PC'!$Q20="","",'MGD PC'!AI20) -> 0
A248: =IF('MGD PC'!$Q21="","",'MGD PC'!Q21) -> MGD PC | B248: =IF('MGD PC'!$Q21="","",'MGD PC'!R21) -> Gate 3 | C248: =IF('MGD PC'!$Q21="","",'MGD PC'!S21) -> Safety Case & Procedure | D248: =IF('MGD PC'!$Q21="","",'MGD PC'!T21) -> Critical risk closure | E248: =IF('MGD PC'!$Q21="","",'MGD PC'!U21) -> Closure of open major safety issues. | F248: =IF('MGD PC'!$Q21="","",'MGD PC'!V21) -> range | G248: =IF('MGD PC'!$Q21="","",'MGD PC'!W21) -> high | H248: =IF('MGD PC'!$Q21="","",'MGD PC'!X21) -> Yes | ... S248: =IF('MGD PC'!$Q21="","",'MGD PC'!AI21) -> 0
A249: =IF('MGD PC'!$Q22="","",'MGD PC'!Q22) -> MGD PC | B249: =IF('MGD PC'!$Q22="","",'MGD PC'!R22) -> Gate 4 | C249: =IF('MGD PC'!$Q22="","",'MGD PC'!S22) -> Business / Assurance | D249: =IF('MGD PC'!$Q22="","",'MGD PC'!T22) -> Cycle benefit | E249: =IF('MGD PC'!$Q22="","",'MGD PC'!U22) -> Cycle improvement from assisted guidance. | F249: =IF('MGD PC'!$Q22="","",'MGD PC'!V22) -> range | G249: =IF('MGD PC'!$Q22="","",'MGD PC'!W22) -> high | H249: =IF('MGD PC'!$Q22="","",'MGD PC'!X22) -> No | ... S249: =IF('MGD PC'!$Q22="","",'MGD PC'!AI22) -> 0
A250: =IF('MGD PC'!$Q23="","",'MGD PC'!Q23) -> MGD PC | B250: =IF('MGD PC'!$Q23="","",'MGD PC'!R23) -> Gate 4 | C250: =IF('MGD PC'!$Q23="","",'MGD PC'!S23) -> Business / Assurance | D250: =IF('MGD PC'!$Q23="","",'MGD PC'!T23) -> Waste / rework gain | E250: =IF('MGD PC'!$Q23="","",'MGD PC'!U23) -> Reduction in avoidable quality loss. | F250: =IF('MGD PC'!$Q23="","",'MGD PC'!V23) -> range | G250: =IF('MGD PC'!$Q23="","",'MGD PC'!W23) -> high | H250: =IF('MGD PC'!$Q23="","",'MGD PC'!X23) -> No | ... S250: =IF('MGD PC'!$Q23="","",'MGD PC'!AI23) -> 0
A251: =IF('MGD PC'!$Q24="","",'MGD PC'!Q24) -> MGD PC | B251: =IF('MGD PC'!$Q24="","",'MGD PC'!R24) -> Gate 4 | C251: =IF('MGD PC'!$Q24="","",'MGD PC'!S24) -> Business / Assurance | D251: =IF('MGD PC'!$Q24="","",'MGD PC'!T24) -> Scale rationale | E251: =IF('MGD PC'!$Q24="","",'MGD PC'!U24) -> Readiness to move beyond proof-of-concept stage. | F251: =IF('MGD PC'!$Q24="","",'MGD PC'!V24) -> select | G251: =IF('MGD PC'!$Q24="","",'MGD PC'!W24) -> 0 | H251: =IF('MGD PC'!$Q24="","",'MGD PC'!X24) -> No | ... S251: =IF('MGD PC'!$Q24="","",'MGD PC'!AI24) -> 0
... A477: =IF('MGD PC'!$Q250="","",'MGD PC'!Q250) -> MGD PC | B477: =IF('MGD PC'!$Q250="","",'MGD PC'!R250) -> 0 | C477: =IF('MGD PC'!$Q250="","",'MGD PC'!S250) -> 0 | D477: =IF('MGD PC'!$Q250="","",'MGD PC'!T250) -> 0 | E477: =IF('MGD PC'!$Q250="","",'MGD PC'!U250) -> 0 | F477: =IF('MGD PC'!$Q250="","",'MGD PC'!V250) -> 0 | G477: =IF('MGD PC'!$Q250="","",'MGD PC'!W250) -> 0 | H477: =IF('MGD PC'!$Q250="","",'MGD PC'!X250) -> 0 | ... S477: =IF('MGD PC'!$Q250="","",'MGD PC'!AI250) -> 0
A478: =IF('Remote Pump'!$Q13="","",'Remote Pump'!Q13) -> Remote Pump | B478: =IF('Remote Pump'!$Q13="","",'Remote Pump'!R13) -> Gate 1 | C478: =IF('Remote Pump'!$Q13="","",'Remote Pump'!S13) -> Technical Feasibility | D478: =IF('Remote Pump'!$Q13="","",'Remote Pump'!T13) -> Command success rate | E478: =IF('Remote Pump'!$Q13="","",'Remote Pump'!U13) -> Success of issued remote command. | F478: =IF('Remote Pump'!$Q13="","",'Remote Pump'!V13) -> range | G478: =IF('Remote Pump'!$Q13="","",'Remote Pump'!W13) -> high | H478: =IF('Remote Pump'!$Q13="","",'Remote Pump'!X13) -> Yes | ... S478: =IF('Remote Pump'!$Q13="","",'Remote Pump'!AI13) -> 0
A479: =IF('Remote Pump'!$Q14="","",'Remote Pump'!Q14) -> Remote Pump | B479: =IF('Remote Pump'!$Q14="","",'Remote Pump'!R14) -> Gate 1 | C479: =IF('Remote Pump'!$Q14="","",'Remote Pump'!S14) -> Technical Feasibility | D479: =IF('Remote Pump'!$Q14="","",'Remote Pump'!T14) -> Telemetry completeness | E479: =IF('Remote Pump'!$Q14="","",'Remote Pump'!U14) -> Availability of remote feedback and audit data. | F479: =IF('Remote Pump'!$Q14="","",'Remote Pump'!V14) -> range | G479: =IF('Remote Pump'!$Q14="","",'Remote Pump'!W14) -> high | H479: =IF('Remote Pump'!$Q14="","",'Remote Pump'!X14) -> No | ... S479: =IF('Remote Pump'!$Q14="","",'Remote Pump'!AI14) -> 0
A480: =IF('Remote Pump'!$Q15="","",'Remote Pump'!Q15) -> Remote Pump | B480: =IF('Remote Pump'!$Q15="","",'Remote Pump'!R15) -> Gate 1 | C480: =IF('Remote Pump'!$Q15="","",'Remote Pump'!S15) -> Technical Feasibility | D480: =IF('Remote Pump'!$Q15="","",'Remote Pump'!T15) -> Communication uptime | E480: =IF('Remote Pump'!$Q15="","",'Remote Pump'!U15) -> Reliability of communication channel. | F480: =IF('Remote Pump'!$Q15="","",'Remote Pump'!V15) -> range | G480: =IF('Remote Pump'!$Q15="","",'Remote Pump'!W15) -> high | H480: =IF('Remote Pump'!$Q15="","",'Remote Pump'!X15) -> Yes | ... S480: =IF('Remote Pump'!$Q15="","",'Remote Pump'!AI15) -> 0
A481: =IF('Remote Pump'!$Q16="","",'Remote Pump'!Q16) -> Remote Pump | B481: =IF('Remote Pump'!$Q16="","",'Remote Pump'!R16) -> Gate 2 | C481: =IF('Remote Pump'!$Q16="","",'Remote Pump'!S16) -> Performance / Effectiveness | D481: =IF('Remote Pump'!$Q16="","",'Remote Pump'!T16) -> Remote availability | E481: =IF('Remote Pump'!$Q16="","",'Remote Pump'!U16) -> Ability to operate remotely when needed. | F481: =IF('Remote Pump'!$Q16="","",'Remote Pump'!V16) -> range | G481: =IF('Remote Pump'!$Q16="","",'Remote Pump'!W16) -> high | H481: =IF('Remote Pump'!$Q16="","",'Remote Pump'!X16) -> No | ... S481: =IF('Remote Pump'!$Q16="","",'Remote Pump'!AI16) -> 0
A482: =IF('Remote Pump'!$Q17="","",'Remote Pump'!Q17) -> Remote Pump | B482: =IF('Remote Pump'!$Q17="","",'Remote Pump'!R17) -> Gate 2 | C482: =IF('Remote Pump'!$Q17="","",'Remote Pump'!S17) -> Performance / Effectiveness | D482: =IF('Remote Pump'!$Q17="","",'Remote Pump'!T17) -> Response latency | E482: =IF('Remote Pump'!$Q17="","",'Remote Pump'!U17) -> Control response time under operating condition. | F482: =IF('Remote Pump'!$Q17="","",'Remote Pump'!V17) -> range | G482: =IF('Remote Pump'!$Q17="","",'Remote Pump'!W17) -> low | H482: =IF('Remote Pump'!$Q17="","",'Remote Pump'!X17) -> No | ... S482: =IF('Remote Pump'!$Q17="","",'Remote Pump'!AI17) -> 0
A483: =IF('Remote Pump'!$Q18="","",'Remote Pump'!Q18) -> Remote Pump | B483: =IF('Remote Pump'!$Q18="","",'Remote Pump'!R18) -> Gate 2 | C483: =IF('Remote Pump'!$Q18="","",'Remote Pump'!S18) -> Performance / Effectiveness | D483: =IF('Remote Pump'!$Q18="","",'Remote Pump'!T18) -> Downtime reduction | E483: =IF('Remote Pump'!$Q18="","",'Remote Pump'!U18) -> Reduction in event-driven downtime. | F483: =IF('Remote Pump'!$Q18="","",'Remote Pump'!V18) -> range | G483: =IF('Remote Pump'!$Q18="","",'Remote Pump'!W18) -> high | H483: =IF('Remote Pump'!$Q18="","",'Remote Pump'!X18) -> No | ... S483: =IF('Remote Pump'!$Q18="","",'Remote Pump'!AI18) -> 0
A484: =IF('Remote Pump'!$Q19="","",'Remote Pump'!Q19) -> Remote Pump | B484: =IF('Remote Pump'!$Q19="","",'Remote Pump'!R19) -> Gate 3 | C484: =IF('Remote Pump'!$Q19="","",'Remote Pump'!S19) -> Safety Case & Procedure | D484: =IF('Remote Pump'!$Q19="","",'Remote Pump'!T19) -> Safety interlock | E484: =IF('Remote Pump'!$Q19="","",'Remote Pump'!U19) -> Integrity of remote command permissive chain. | F484: =IF('Remote Pump'!$Q19="","",'Remote Pump'!V19) -> select | G484: =IF('Remote Pump'!$Q19="","",'Remote Pump'!W19) -> 0 | H484: =IF('Remote Pump'!$Q19="","",'Remote Pump'!X19) -> Yes | ... S484: =IF('Remote Pump'!$Q19="","",'Remote Pump'!AI19) -> 0
A485: =IF('Remote Pump'!$Q20="","",'Remote Pump'!Q20) -> Remote Pump | B485: =IF('Remote Pump'!$Q20="","",'Remote Pump'!R20) -> Gate 3 | C485: =IF('Remote Pump'!$Q20="","",'Remote Pump'!S20) -> Safety Case & Procedure | D485: =IF('Remote Pump'!$Q20="","",'Remote Pump'!T20) -> Loss-of-signal fail-safe | E485: =IF('Remote Pump'!$Q20="","",'Remote Pump'!U20) -> Safe fallback when signal is lost. | F485: =IF('Remote Pump'!$Q20="","",'Remote Pump'!V20) -> select | G485: =IF('Remote Pump'!$Q20="","",'Remote Pump'!W20) -> 0 | H485: =IF('Remote Pump'!$Q20="","",'Remote Pump'!X20) -> Yes | ... S485: =IF('Remote Pump'!$Q20="","",'Remote Pump'!AI20) -> 0
